<robot name="Vision_Rpi_Bot">

    <link name="base_footprint" />

    <!--///////////////////////////////////////////////BASE LINK///////////////////////////////////////////////////////-->

    <link name="base_link">
        <visual>
            <geometry>
                <mesh filename="package://vision_rpi_bot/meshes/base.dae"/>
            </geometry>
        </visual>

        <collision>
            <geometry>
                <mesh filename="package://vision_rpi_bot/meshes/base.dae"/>
            </geometry>
        </collision>

        <inertial>
            <mass value="10"/>
            <inertia ixx="0.4" ixy="0.0" ixz="0.0" iyy="0.4" iyz="0.0" izz="0.2"/>
        </inertial>

    </link>

    <joint name="base_joint" type="fixed">
        <parent link="base_footprint" />
        <child link="base_link" />
        <origin rpy="0 0 0" xyz="0 0 0.14" />
    </joint>


    <!--///////////////////////////////////////////////CASTER HOLDER LINK///////////////////////////////////////////////////////-->

    <link name="caster_holder_link">
        <visual>
            <geometry>
                <mesh filename="package://vision_rpi_bot/meshes/caster_holder.dae"/>
            </geometry>
        </visual>

        <collision>
            <geometry>
                <mesh filename="package://vision_rpi_bot/meshes/caster_holder.dae"/>
            </geometry>
        </collision>

        <inertial>
            <mass value="10"/>
            <inertia ixx="0.4" ixy="0.0" ixz="0.0" iyy="0.4" iyz="0.0" izz="0.2"/>
        </inertial>

    </link>

    <joint name="caster_holder_joint" type="fixed">
        <parent link="base_link" />
        <child link="caster_holder_link" />
        <origin rpy="0 0 0" xyz="0 0 0.14" />
    </joint>


        <!--///////////////////////////////////////////////CASTER WHEEL LINK///////////////////////////////////////////////////////-->

    <link name="caster_wheel_link">
        <visual>
            <geometry>
                <mesh filename="package://vision_rpi_bot/meshes/caster_wheel.dae"/>
            </geometry>
        </visual>

        <collision>
            <geometry>
                <mesh filename="package://vision_rpi_bot/meshes/caster_wheel.dae"/>
            </geometry>
        </collision>

        <inertial>
            <mass value="10"/>
            <inertia ixx="0.4" ixy="0.0" ixz="0.0" iyy="0.4" iyz="0.0" izz="0.2"/>
        </inertial>

    </link>

    <joint name="caster_wheel_joint" type="continuous">
        <axis xyz="1 0.0 0.0"/>
        <parent link="base_link" />
        <child link="caster_wheel_link" />
        <origin rpy="0 0 0" xyz="0 0 0.14" />
    </joint>




        <!--///////////////////////////////////////////////RIGHT WHEEL LINK///////////////////////////////////////////////////////-->

    <link name="right_wheel_link">
        <visual>
            <geometry>
                <mesh filename="package://vision_rpi_bot/meshes/wheel.dae"/>
            </geometry>
        </visual>

        <collision>
            <geometry>
                <mesh filename="package://vision_rpi_bot/meshes/wheel.dae"/>
            </geometry>
        </collision>

        <inertial>
            <mass value="10"/>
            <inertia ixx="0.4" ixy="0.0" ixz="0.0" iyy="0.4" iyz="0.0" izz="0.2"/>
        </inertial>

    </link>

    <joint name="right_wheel_joint" type="continuous">
        <axis xyz="0.0 1 0.0"/>
        <parent link="base_link" />
        <child link="right_wheel_link" />
        <origin rpy="0 0 0" xyz="0 0 0.14" />
    </joint>



        <!--///////////////////////////////////////////////LEFT WHEEL LINK///////////////////////////////////////////////////////-->

    <link name="left_wheel_link">
        <visual>
            <geometry>
                <mesh filename="package://vision_rpi_bot/meshes/wheel.dae"/>
            </geometry>
        </visual>

        <collision>
            <geometry>
                <mesh filename="package://vision_rpi_bot/meshes/wheel.dae"/>
            </geometry>
        </collision>

        <inertial>
            <mass value="10"/>
            <inertia ixx="0.4" ixy="0.0" ixz="0.0" iyy="0.4" iyz="0.0" izz="0.2"/>
        </inertial>

    </link>

    <joint name="left_wheel_joint" type="continuous">
        <axis xyz="0.0 1 0.0"/>
        <parent link="base_link" />
        <child link="left_wheel_link" />
        <origin rpy="0 0 0" xyz="0 0 0.14" />
    </joint>


        <!--///////////////////////////////////////////////CAMERA LINK///////////////////////////////////////////////////////-->

    <link name="camera_link">
        <visual>
            <geometry>
                <mesh filename="package://vision_rpi_bot/meshes/rpi_camera.dae"/>
            </geometry>
        </visual>

        <collision>
            <geometry>
                <mesh filename="package://vision_rpi_bot/meshes/rpi_camera.dae"/>
            </geometry>
        </collision>

        <inertial>
            <mass value="10"/>
            <inertia ixx="0.4" ixy="0.0" ixz="0.0" iyy="0.4" iyz="0.0" izz="0.2"/>
        </inertial>

    </link>

    <joint name="camera_joint" type="fixed">
        <parent link="base_link" />
        <child link="camera_link" />
        <origin rpy="0 0 0" xyz="0 0 0.14" />
    </joint>

       <!--///////////////////////////////////////////////COVER LINK///////////////////////////////////////////////////////-->

    <link name="cover_link">
        <visual>
            <geometry>
                <mesh filename="package://vision_rpi_bot/meshes/cover.dae"/>
            </geometry>
        </visual>

        <collision>
            <geometry>
                <mesh filename="package://vision_rpi_bot/meshes/cover.dae"/>
            </geometry>
        </collision>

        <inertial>
            <mass value="10"/>
            <inertia ixx="0.4" ixy="0.0" ixz="0.0" iyy="0.4" iyz="0.0" izz="0.2"/>
        </inertial>

    </link>

    <joint name="cover_joint" type="fixed">
        <parent link="base_link" />
        <child link="cover_link" />
        <origin rpy="0 0 0" xyz="0 0 0.14" />
    </joint>

</robot>